<?xml version="1.0" ?>
<!-- =================================================================================== -->
<!-- |    This document was autogenerated by xacro from ranger_mini_gazebo.xacro       | -->
<!-- |    EDITING THIS FILE BY HAND IS NOT RECOMMENDED                                 | -->
<!-- =================================================================================== -->
<robot name="ranger_mini_v2">
  <!-- Base -->
  <link name="base_footprint"/>
  <joint name="base_link_joint" type="fixed">
    <origin xyz="0 0 -0.32"/>
    <parent link="base_link"/>
    <child link="base_footprint"/>
  </joint>
  <!-- Base link -->
  <link name="base_link">
    <inertial>
      <origin xyz="0.0 0.0 0.0"/>
      <mass value="10"/>
      <inertia ixx="1" ixy="0.0" ixz="0.0" iyy="1" iyz="0.0" izz="1"/>
    </inertial>
    <visual>
      <!-- <origin rpy="1.57 0 3.14 " xyz="0 0 0"/> -->
      <origin rpy="0 0 0 " xyz="0 0 -0.05"/> #自己添加，减少载入时间
      <geometry>
        <!-- <mesh filename="package://mycarto/meshes/ranger_base.dae"/> -->
        <box size="0.7 0.35 0.1" /> #自己添加，减少载入时间
      </geometry>
      <material name="gray" /> #自己添加，减少载入时间
    </visual>
    <collision>
      <origin rpy="0 0 0" xyz="0 0 -0.1"/>
      <geometry>
        <box size="0.5 0.35 0.2"/>
      </geometry>
    </collision>
  </link>
  <link name="fl_steering_wheel_link">
    <inertial>
      <origin xyz="0.0 0.0 0.0"/>
      <mass value="1"/>
      <inertia ixx="0.01" ixy="0.0" ixz="0.0" iyy="0.01" iyz="0.0" izz="0.01"/>
    </inertial>
    <visual>
      <origin rpy="1.57 0 3.14 " xyz="-0.23 -0.194 0.1"/>
      <geometry>
        <mesh filename="package://mycarto/meshes/fl.dae"/>
      </geometry>
    </visual>
    <collision>
      <origin rpy="0 0 0" xyz="0 0 0.008"/>
      <geometry>
        <cylinder length="0.001" radius="0.001"/>
      </geometry>
    </collision>
    <collision>
      <origin rpy="0 0 0" xyz="0 0 0"/>
      <geometry>
        <cylinder length="0.001" radius="0.001"/>
      </geometry>
    </collision>
  </link>
  <joint name="fl_steering_wheel" type="revolute">
    <origin rpy="0 0 0" xyz="0.23 0.206 -0.1"/>
    <parent link="base_link"/>
    <child link="fl_steering_wheel_link"/>
    <axis rpy="0 0 0" xyz="0 0 1"/>
    <limit effort="5" lower="-2.1" upper="2.1" velocity="6.28"/>
  </joint>
  <link name="fl_wheel_link">
    <inertial>
      <mass value="8"/>
      <origin xyz="0 0 0"/>
      <inertia ixx="0.1171" ixy="0" ixz="0" iyy="0.1361" iyz="0" izz="0.1171"/>
    </inertial>
    <visual>
      <origin rpy="1.57 0 0" xyz="0 0 0"/>
      <geometry>
        <cylinder length="0.01" radius="0.01"/>
      </geometry>
    </visual>
    <collision>
      <origin rpy="1.57 0 0" xyz="0 0 0"/>
      <geometry>
        <cylinder length="0.08" radius="0.08"/>
      </geometry>
      <contact>
        <ode>
          <min_depth>0.001</min_depth>
        </ode>
      </contact>
    </collision>
  </link>
  <joint name="fl_wheel" type="continuous">
    <origin rpy="0 0 0" xyz="0.03 0.01 -0.12"/>
    <parent link="fl_steering_wheel_link"/>
    <child link="fl_wheel_link"/>
    <axis rpy="0 0 0" xyz="0 1 0"/>
  </joint>
  <link name="fr_steering_wheel_link">
    <inertial>
      <origin rpy="0.0 0.0 0.0" xyz="0.0 0.0 0.0"/>
      <mass value="1"/>
      <inertia ixx="0.01" ixy="0.0" ixz="0.0" iyy="0.01" iyz="0.0" izz="0.01"/>
    </inertial>
    <visual>
      <origin rpy="1.57 0 3.14 " xyz="-0.23 0.194 0.1"/>
      <geometry>
        <mesh filename="package://mycarto/meshes/fr.dae"/>
      </geometry>
    </visual>
    <collision>
      <origin rpy="0 0 0" xyz="0 0 0.008"/>
      <geometry>
        <cylinder length="0.001" radius="0.001"/>
      </geometry>
    </collision>
  </link>
  <joint name="fr_steering_wheel" type="revolute">
    <origin rpy="0 0 0" xyz="0.23 -0.206 -0.1"/>
    <parent link="base_link"/>
    <child link="fr_steering_wheel_link"/>
    <axis rpy="0 0 0" xyz="0 0 1"/>
    <limit effort="5" lower="-2.1" upper="2.1" velocity="6.28"/>
  </joint>
  <link name="fr_wheel_link">
    <inertial>
      <mass value="8"/>
      <origin xyz="0 0 0"/>
      <inertia ixx="0.1171" ixy="0" ixz="0" iyy="0.1361" iyz="0" izz="0.1171"/>
    </inertial>
    <visual>
      <origin rpy="1.57 0 0" xyz="0 0 0"/>
      <geometry>
        <cylinder length="0.01" radius="0.01"/>
      </geometry>
    </visual>
    <collision>
      <origin rpy="1.57 0 0" xyz="0 0 0"/>
      <geometry>
        <cylinder length="0.08" radius="0.085"/>
      </geometry>
      <contact>
        <ode>
          <min_depth>0.001</min_depth>
        </ode>
      </contact>
    </collision>
  </link>
  <joint name="fr_wheel" type="continuous">
    <origin rpy="0 0 0" xyz="0.0 0.0 -0.12"/>
    <parent link="fr_steering_wheel_link"/>
    <child link="fr_wheel_link"/>
    <axis rpy="0 0 0" xyz="0 1 0"/>
  </joint>
  <link name="rl_steering_wheel_link">
    <inertial>
      <origin rpy="0.0 0.0 0.0" xyz="0.0 0.0 0.0"/>
      <mass value="1"/>
      <inertia ixx="0.01" ixy="0.0" ixz="0.0" iyy="0.01" iyz="0.0" izz="0.01"/>
    </inertial>
    <visual>
      <origin rpy="1.57 0 3.14 " xyz="-0.23 -0.194 0.1"/>
      <geometry>
        <mesh filename="package://mycarto/meshes/fl.dae"/>
      </geometry>
    </visual>
    <collision>
      <origin rpy="0 0 0" xyz="0 0 0.008"/>
      <geometry>
        <cylinder length="0.001" radius="0.001"/>
      </geometry>
    </collision>
  </link>
  <joint name="rl_steering_wheel" type="revolute">
    <origin rpy="0 0 0" xyz="-0.23 0.206 -0.1"/>
    <parent link="base_link"/>
    <child link="rl_steering_wheel_link"/>
    <axis rpy="0 0 0" xyz="0 0 1"/>
    <limit effort="5" lower="-2.1" upper="2.1" velocity="6.28"/>
  </joint>
  <link name="rl_wheel_link">
    <inertial>
      <mass value="8"/>
      <origin xyz="0 0 0"/>
      <inertia ixx="0.1171" ixy="0" ixz="0" iyy="0.1361" iyz="0" izz="0.1171"/>
    </inertial>
    <visual>
      <origin rpy="1.57 0 0" xyz="0 0 0"/>
      <geometry>
        <cylinder length="0.01" radius="0.01"/>
      </geometry>
    </visual>
    <collision>
      <origin rpy="1.57 0 0" xyz="0 0 0"/>
      <geometry>
        <cylinder length="0.08" radius="0.08"/>
      </geometry>
      <contact>
        <ode>
          <min_depth>0.001</min_depth>
        </ode>
      </contact>
    </collision>
  </link>
  <joint name="rl_wheel" type="continuous">
    <origin rpy="0 0 0" xyz="0.0 0.0 -0.12 "/>
    <parent link="rl_steering_wheel_link"/>
    <child link="rl_wheel_link"/>
    <axis rpy="0 0 0" xyz="0 1 0"/>
  </joint>
  <link name="rr_steering_wheel_link">
    <inertial>
      <origin xyz="0.0 0.0 0.0"/>
      <mass value="1"/>
      <inertia ixx="0.01" ixy="0.0" ixz="0.0" iyy="0.01" iyz="0.0" izz="0.01"/>
    </inertial>
    <visual>
      <origin rpy="1.57 0 3.14 " xyz="-0.23 0.194 0.1"/>
      <geometry>
        <mesh filename="package://mycarto/meshes/fr.dae"/>
      </geometry>
    </visual>
    <collision>
      <origin rpy="0 0 0" xyz="0 0 0"/>
      <geometry>
        <cylinder length="0.001" radius="0.001"/>
      </geometry>
    </collision>
  </link>
  <joint name="rr_steering_wheel" type="revolute">
    <origin rpy="0 0 0" xyz="-0.23 -0.206 -0.1"/>
    <parent link="base_link"/>
    <child link="rr_steering_wheel_link"/>
    <axis rpy="0 0 0" xyz="0 0 1"/>
    <limit effort="5" lower="-2.1" upper="2.1" velocity="6.28"/>
  </joint>
  <link name="rr_wheel_link">
    <inertial>
      <mass value="8"/>
      <origin xyz="0 0 0"/>
      <inertia ixx="0.1171" ixy="0" ixz="0" iyy="0.1361" iyz="0" izz="0.1171"/>
    </inertial>
    <visual>
      <origin rpy="1.57 0 0" xyz="0.0 0.0 0.0"/>
      <geometry>
        <cylinder length="0.01" radius="0.01"/>
      </geometry>
    </visual>
    <collision>
      <origin rpy="1.57 0 0" xyz="0 0 0"/>
      <geometry>
        <cylinder length="0.08" radius="0.08"/>
      </geometry>
      <contact>
        <ode>
          <min_depth>0.001</min_depth>
        </ode>
      </contact>
    </collision>
  </link>
  <joint name="rr_wheel" type="continuous">
    <origin rpy="0 0 0" xyz="0.0 0.0 -0.12 "/>
    <parent link="rr_steering_wheel_link"/>
    <child link="rr_wheel_link"/>
    <axis rpy="0 0 0" xyz="0 1 0"/>
  </joint>



  <material name="orange">
    <color rgba="1.0 0.5 0.2 1" />
  </material>
  <material name="gray">
    <color rgba="0.2 0.2 0.2 1" />
  </material>
 

  <link name="scanner_link">#与雷达的fram_id对应
    <visual>
      <origin xyz="0 0 0" />
      <geometry>
        <cylinder length="0.1" radius="0.03" />
      </geometry>
      <material name="gray" />
    </visual>
  </link>
   <link name="imu_link">#与imu的fram_id对应
    <visual>
      <origin xyz="0 0 0" />
      <geometry>
        <box size="0.02 0.02 0.02" />
      </geometry>
      <material name="orange" />
    </visual>
  </link>
 
  <joint name="laser2robot" type="fixed">
    <parent link="base_link" />
    <child link="scanner_link" />
    <origin xyz="0.3 0 0" rpy="0 0 1.5708"/>
  </joint>

    <!-- <joint name="imu2robot" type="fixed">
    <parent link="base_link" />
    <child link="imu_link" />
    <origin xyz="-0.3 0 0" rpy="0 0 0"/>
  </joint> -->

    <joint name="imu2laser" type="fixed">
    <parent link="scanner_link" />
    <child link="imu_link" />
    <origin xyz="0 0.35 0" rpy="0 0 -1.5708"/>
  </joint> 






  
</robot>